[2025-02-17T22:49:38.678+0000] {local_task_job_runner.py:123} INFO - ::group::Pre task execution logs
[2025-02-17T22:49:38.708+0000] {taskinstance.py:2613} INFO - Dependencies all met for dep_context=non-requeueable deps ti=<TaskInstance: dbt_run.run_dbt scheduled__2025-02-17T22:30:00+00:00 [queued]>
[2025-02-17T22:49:38.726+0000] {taskinstance.py:2613} INFO - Dependencies all met for dep_context=requeueable deps ti=<TaskInstance: dbt_run.run_dbt scheduled__2025-02-17T22:30:00+00:00 [queued]>
[2025-02-17T22:49:38.728+0000] {taskinstance.py:2866} INFO - Starting attempt 2 of 3
[2025-02-17T22:49:38.779+0000] {taskinstance.py:2889} INFO - Executing <Task(BashOperator): run_dbt> on 2025-02-17 22:30:00+00:00
[2025-02-17T22:49:38.795+0000] {standard_task_runner.py:104} INFO - Running: ['***', 'tasks', 'run', 'dbt_run', 'run_dbt', 'scheduled__2025-02-17T22:30:00+00:00', '--job-id', '4', '--raw', '--subdir', 'DAGS_FOLDER/dbt_run_dag.py', '--cfg-path', '/tmp/tmpgqb2o30w']
[2025-02-17T22:49:38.800+0000] {standard_task_runner.py:105} INFO - Job 4: Subtask run_dbt
[2025-02-17T22:49:38.812+0000] {logging_mixin.py:190} WARNING - /home/***/.local/lib/python3.12/site-packages/***/task/task_runner/standard_task_runner.py:70 DeprecationWarning: This process (pid=242) is multi-threaded, use of fork() may lead to deadlocks in the child.
[2025-02-17T22:49:38.814+0000] {standard_task_runner.py:72} INFO - Started process 243 to run task
[2025-02-17T22:49:38.890+0000] {task_command.py:467} INFO - Running <TaskInstance: dbt_run.run_dbt scheduled__2025-02-17T22:30:00+00:00 [running]> on host 546d661258c0
[2025-02-17T22:49:39.015+0000] {taskinstance.py:3132} INFO - Exporting env vars: AIRFLOW_CTX_DAG_OWNER='***' AIRFLOW_CTX_DAG_ID='dbt_run' AIRFLOW_CTX_TASK_ID='run_dbt' AIRFLOW_CTX_EXECUTION_DATE='2025-02-17T22:30:00+00:00' AIRFLOW_CTX_TRY_NUMBER='2' AIRFLOW_CTX_DAG_RUN_ID='scheduled__2025-02-17T22:30:00+00:00'
[2025-02-17T22:49:39.017+0000] {taskinstance.py:731} INFO - ::endgroup::
[2025-02-17T22:49:39.041+0000] {subprocess.py:78} INFO - Tmp dir root location: /tmp
[2025-02-17T22:49:39.043+0000] {subprocess.py:88} INFO - Running command: ['/usr/bin/bash', '-c', 'cd /fitness-data-pipeline && dbt run']
[2025-02-17T22:49:39.058+0000] {subprocess.py:99} INFO - Output:
[2025-02-17T22:49:42.133+0000] {subprocess.py:106} INFO - [0m22:49:42  Running with dbt=1.9.2
[2025-02-17T22:49:42.136+0000] {subprocess.py:106} INFO - [0m22:49:42  Encountered an error:
[2025-02-17T22:49:42.137+0000] {subprocess.py:106} INFO - Runtime Error
[2025-02-17T22:49:42.138+0000] {subprocess.py:106} INFO -   No dbt_project.yml found at expected path /fitness-data-pipeline/dbt_project.yml
[2025-02-17T22:49:42.139+0000] {subprocess.py:106} INFO -   Verify that each entry within packages.yml (and their transitive dependencies) contains a file named dbt_project.yml
[2025-02-17T22:49:42.141+0000] {subprocess.py:106} INFO - 
[2025-02-17T22:49:43.199+0000] {subprocess.py:110} INFO - Command exited with return code 2
[2025-02-17T22:49:43.217+0000] {taskinstance.py:3311} ERROR - Task failed with exception
Traceback (most recent call last):
  File "/home/airflow/.local/lib/python3.12/site-packages/airflow/models/taskinstance.py", line 767, in _execute_task
    result = _execute_callable(context=context, **execute_callable_kwargs)
             ^^^^^^^^^^^^^^^^^^^^^^^^^^^^^^^^^^^^^^^^^^^^^^^^^^^^^^^^^^^^^
  File "/home/airflow/.local/lib/python3.12/site-packages/airflow/models/taskinstance.py", line 733, in _execute_callable
    return ExecutionCallableRunner(
           ^^^^^^^^^^^^^^^^^^^^^^^^
  File "/home/airflow/.local/lib/python3.12/site-packages/airflow/utils/operator_helpers.py", line 252, in run
    return self.func(*args, **kwargs)
           ^^^^^^^^^^^^^^^^^^^^^^^^^^
  File "/home/airflow/.local/lib/python3.12/site-packages/airflow/models/baseoperator.py", line 422, in wrapper
    return func(self, *args, **kwargs)
           ^^^^^^^^^^^^^^^^^^^^^^^^^^^
  File "/home/airflow/.local/lib/python3.12/site-packages/airflow/operators/bash.py", line 276, in execute
    raise AirflowException(
airflow.exceptions.AirflowException: Bash command failed. The command returned a non-zero exit code 2.
[2025-02-17T22:49:43.228+0000] {taskinstance.py:1225} INFO - Marking task as UP_FOR_RETRY. dag_id=dbt_run, task_id=run_dbt, run_id=scheduled__2025-02-17T22:30:00+00:00, execution_date=20250217T223000, start_date=20250217T224938, end_date=20250217T224943
[2025-02-17T22:49:43.271+0000] {taskinstance.py:340} INFO - ::group::Post task execution logs
[2025-02-17T22:49:43.273+0000] {standard_task_runner.py:124} ERROR - Failed to execute job 4 for task run_dbt (Bash command failed. The command returned a non-zero exit code 2.; 243)
Traceback (most recent call last):
  File "/home/airflow/.local/lib/python3.12/site-packages/airflow/task/task_runner/standard_task_runner.py", line 117, in _start_by_fork
    ret = args.func(args, dag=self.dag)
          ^^^^^^^^^^^^^^^^^^^^^^^^^^^^^
  File "/home/airflow/.local/lib/python3.12/site-packages/airflow/cli/cli_config.py", line 49, in command
    return func(*args, **kwargs)
           ^^^^^^^^^^^^^^^^^^^^^
  File "/home/airflow/.local/lib/python3.12/site-packages/airflow/utils/cli.py", line 116, in wrapper
    return f(*args, **kwargs)
           ^^^^^^^^^^^^^^^^^^
  File "/home/airflow/.local/lib/python3.12/site-packages/airflow/cli/commands/task_command.py", line 483, in task_run
    task_return_code = _run_task_by_selected_method(args, _dag, ti)
                       ^^^^^^^^^^^^^^^^^^^^^^^^^^^^^^^^^^^^^^^^^^^^
  File "/home/airflow/.local/lib/python3.12/site-packages/airflow/cli/commands/task_command.py", line 256, in _run_task_by_selected_method
    return _run_raw_task(args, ti)
           ^^^^^^^^^^^^^^^^^^^^^^^
  File "/home/airflow/.local/lib/python3.12/site-packages/airflow/cli/commands/task_command.py", line 341, in _run_raw_task
    return ti._run_raw_task(
           ^^^^^^^^^^^^^^^^^
  File "/home/airflow/.local/lib/python3.12/site-packages/airflow/utils/session.py", line 97, in wrapper
    return func(*args, session=session, **kwargs)
           ^^^^^^^^^^^^^^^^^^^^^^^^^^^^^^^^^^^^^^
  File "/home/airflow/.local/lib/python3.12/site-packages/airflow/models/taskinstance.py", line 3005, in _run_raw_task
    return _run_raw_task(
           ^^^^^^^^^^^^^^
  File "/home/airflow/.local/lib/python3.12/site-packages/airflow/models/taskinstance.py", line 273, in _run_raw_task
    TaskInstance._execute_task_with_callbacks(
  File "/home/airflow/.local/lib/python3.12/site-packages/airflow/models/taskinstance.py", line 3159, in _execute_task_with_callbacks
    result = self._execute_task(context, task_orig)
             ^^^^^^^^^^^^^^^^^^^^^^^^^^^^^^^^^^^^^^
  File "/home/airflow/.local/lib/python3.12/site-packages/airflow/models/taskinstance.py", line 3183, in _execute_task
    return _execute_task(self, context, task_orig)
           ^^^^^^^^^^^^^^^^^^^^^^^^^^^^^^^^^^^^^^^
  File "/home/airflow/.local/lib/python3.12/site-packages/airflow/models/taskinstance.py", line 767, in _execute_task
    result = _execute_callable(context=context, **execute_callable_kwargs)
             ^^^^^^^^^^^^^^^^^^^^^^^^^^^^^^^^^^^^^^^^^^^^^^^^^^^^^^^^^^^^^
  File "/home/airflow/.local/lib/python3.12/site-packages/airflow/models/taskinstance.py", line 733, in _execute_callable
    return ExecutionCallableRunner(
           ^^^^^^^^^^^^^^^^^^^^^^^^
  File "/home/airflow/.local/lib/python3.12/site-packages/airflow/utils/operator_helpers.py", line 252, in run
    return self.func(*args, **kwargs)
           ^^^^^^^^^^^^^^^^^^^^^^^^^^
  File "/home/airflow/.local/lib/python3.12/site-packages/airflow/models/baseoperator.py", line 422, in wrapper
    return func(self, *args, **kwargs)
           ^^^^^^^^^^^^^^^^^^^^^^^^^^^
  File "/home/airflow/.local/lib/python3.12/site-packages/airflow/operators/bash.py", line 276, in execute
    raise AirflowException(
airflow.exceptions.AirflowException: Bash command failed. The command returned a non-zero exit code 2.
[2025-02-17T22:49:43.294+0000] {local_task_job_runner.py:266} INFO - Task exited with return code 1
[2025-02-17T22:49:43.324+0000] {taskinstance.py:3895} INFO - 0 downstream tasks scheduled from follow-on schedule check
[2025-02-17T22:49:43.329+0000] {local_task_job_runner.py:245} INFO - ::endgroup::
