[2025-02-18T16:07:38.015+0000] {local_task_job_runner.py:123} INFO - ::group::Pre task execution logs
[2025-02-18T16:07:38.047+0000] {taskinstance.py:2613} INFO - Dependencies all met for dep_context=non-requeueable deps ti=<TaskInstance: dbt_run.run_dbt scheduled__2025-02-18T15:40:00+00:00 [queued]>
[2025-02-18T16:07:38.064+0000] {taskinstance.py:2613} INFO - Dependencies all met for dep_context=requeueable deps ti=<TaskInstance: dbt_run.run_dbt scheduled__2025-02-18T15:40:00+00:00 [queued]>
[2025-02-18T16:07:38.066+0000] {taskinstance.py:2866} INFO - Starting attempt 2 of 2
[2025-02-18T16:07:38.090+0000] {taskinstance.py:2889} INFO - Executing <Task(BashOperator): run_dbt> on 2025-02-18 15:40:00+00:00
[2025-02-18T16:07:38.104+0000] {standard_task_runner.py:104} INFO - Running: ['***', 'tasks', 'run', 'dbt_run', 'run_dbt', 'scheduled__2025-02-18T15:40:00+00:00', '--job-id', '33', '--raw', '--subdir', 'DAGS_FOLDER/dbt_run_dag.py', '--cfg-path', '/tmp/tmpqfqfuh7x']
[2025-02-18T16:07:38.109+0000] {standard_task_runner.py:105} INFO - Job 33: Subtask run_dbt
[2025-02-18T16:07:38.119+0000] {logging_mixin.py:190} WARNING - /home/***/.local/lib/python3.12/site-packages/***/task/task_runner/standard_task_runner.py:70 DeprecationWarning: This process (pid=1094) is multi-threaded, use of fork() may lead to deadlocks in the child.
[2025-02-18T16:07:38.120+0000] {standard_task_runner.py:72} INFO - Started process 1095 to run task
[2025-02-18T16:07:38.211+0000] {task_command.py:467} INFO - Running <TaskInstance: dbt_run.run_dbt scheduled__2025-02-18T15:40:00+00:00 [running]> on host eeda3fda8711
[2025-02-18T16:07:38.383+0000] {taskinstance.py:3132} INFO - Exporting env vars: AIRFLOW_CTX_DAG_OWNER='***' AIRFLOW_CTX_DAG_ID='dbt_run' AIRFLOW_CTX_TASK_ID='run_dbt' AIRFLOW_CTX_EXECUTION_DATE='2025-02-18T15:40:00+00:00' AIRFLOW_CTX_TRY_NUMBER='2' AIRFLOW_CTX_DAG_RUN_ID='scheduled__2025-02-18T15:40:00+00:00'
[2025-02-18T16:07:38.385+0000] {taskinstance.py:731} INFO - ::endgroup::
[2025-02-18T16:07:38.409+0000] {subprocess.py:78} INFO - Tmp dir root location: /tmp
[2025-02-18T16:07:38.411+0000] {subprocess.py:88} INFO - Running command: ['/usr/bin/bash', '-c', 'cd /fitness-data-pipeline && dbt run']
[2025-02-18T16:07:38.423+0000] {subprocess.py:99} INFO - Output:
[2025-02-18T16:07:41.333+0000] {subprocess.py:106} INFO - [0m16:07:41  Running with dbt=1.9.2
[2025-02-18T16:07:42.550+0000] {subprocess.py:106} INFO - [0m16:07:42  Registered adapter: bigquery=1.9.1
[2025-02-18T16:07:43.299+0000] {subprocess.py:106} INFO - [0m16:07:43  Encountered an error:
[2025-02-18T16:07:43.299+0000] {subprocess.py:106} INFO - 'dbt_bigquery://macros/adapters.sql'
[2025-02-18T16:07:43.300+0000] {subprocess.py:106} INFO - [0m16:07:43  Traceback (most recent call last):
[2025-02-18T16:07:43.302+0000] {subprocess.py:106} INFO -   File "/home/***/.local/lib/python3.12/site-packages/dbt/cli/requires.py", line 153, in wrapper
[2025-02-18T16:07:43.303+0000] {subprocess.py:106} INFO -     result, success = func(*args, **kwargs)
[2025-02-18T16:07:43.304+0000] {subprocess.py:106} INFO -                       ^^^^^^^^^^^^^^^^^^^^^
[2025-02-18T16:07:43.305+0000] {subprocess.py:106} INFO -   File "/home/***/.local/lib/python3.12/site-packages/dbt/cli/requires.py", line 103, in wrapper
[2025-02-18T16:07:43.306+0000] {subprocess.py:106} INFO -     return func(*args, **kwargs)
[2025-02-18T16:07:43.307+0000] {subprocess.py:106} INFO -            ^^^^^^^^^^^^^^^^^^^^^
[2025-02-18T16:07:43.308+0000] {subprocess.py:106} INFO -   File "/home/***/.local/lib/python3.12/site-packages/dbt/cli/requires.py", line 235, in wrapper
[2025-02-18T16:07:43.309+0000] {subprocess.py:106} INFO -     return func(*args, **kwargs)
[2025-02-18T16:07:43.311+0000] {subprocess.py:106} INFO -            ^^^^^^^^^^^^^^^^^^^^^
[2025-02-18T16:07:43.311+0000] {subprocess.py:106} INFO -   File "/home/***/.local/lib/python3.12/site-packages/dbt/cli/requires.py", line 264, in wrapper
[2025-02-18T16:07:43.312+0000] {subprocess.py:106} INFO -     return func(*args, **kwargs)
[2025-02-18T16:07:43.313+0000] {subprocess.py:106} INFO -            ^^^^^^^^^^^^^^^^^^^^^
[2025-02-18T16:07:43.314+0000] {subprocess.py:106} INFO -   File "/home/***/.local/lib/python3.12/site-packages/dbt/cli/requires.py", line 311, in wrapper
[2025-02-18T16:07:43.314+0000] {subprocess.py:106} INFO -     return func(*args, **kwargs)
[2025-02-18T16:07:43.316+0000] {subprocess.py:106} INFO -            ^^^^^^^^^^^^^^^^^^^^^
[2025-02-18T16:07:43.317+0000] {subprocess.py:106} INFO -   File "/home/***/.local/lib/python3.12/site-packages/dbt/cli/requires.py", line 327, in wrapper
[2025-02-18T16:07:43.318+0000] {subprocess.py:106} INFO -     setup_manifest(ctx, write=write, write_perf_info=write_perf_info)
[2025-02-18T16:07:43.318+0000] {subprocess.py:106} INFO -   File "/home/***/.local/lib/python3.12/site-packages/dbt/cli/requires.py", line 351, in setup_manifest
[2025-02-18T16:07:43.319+0000] {subprocess.py:106} INFO -     ctx.obj["manifest"] = parse_manifest(
[2025-02-18T16:07:43.319+0000] {subprocess.py:106} INFO -                           ^^^^^^^^^^^^^^^
[2025-02-18T16:07:43.319+0000] {subprocess.py:106} INFO -   File "/home/***/.local/lib/python3.12/site-packages/dbt/parser/manifest.py", line 2069, in parse_manifest
[2025-02-18T16:07:43.320+0000] {subprocess.py:106} INFO -     manifest = ManifestLoader.get_full_manifest(
[2025-02-18T16:07:43.321+0000] {subprocess.py:106} INFO -                ^^^^^^^^^^^^^^^^^^^^^^^^^^^^^^^^^
[2025-02-18T16:07:43.321+0000] {subprocess.py:106} INFO -   File "/home/***/.local/lib/python3.12/site-packages/dbt/parser/manifest.py", line 312, in get_full_manifest
[2025-02-18T16:07:43.323+0000] {subprocess.py:106} INFO -     manifest = loader.load()
[2025-02-18T16:07:43.324+0000] {subprocess.py:106} INFO -                ^^^^^^^^^^^^^
[2025-02-18T16:07:43.325+0000] {subprocess.py:106} INFO -   File "/home/***/.local/lib/python3.12/site-packages/dbt/parser/manifest.py", line 381, in load
[2025-02-18T16:07:43.326+0000] {subprocess.py:106} INFO -     self.load_and_parse_macros(project_parser_files)
[2025-02-18T16:07:43.326+0000] {subprocess.py:106} INFO -   File "/home/***/.local/lib/python3.12/site-packages/dbt/parser/manifest.py", line 683, in load_and_parse_macros
[2025-02-18T16:07:43.326+0000] {subprocess.py:106} INFO -     block = FileBlock(self.manifest.files[file_id])
[2025-02-18T16:07:43.327+0000] {subprocess.py:106} INFO -                       ~~~~~~~~~~~~~~~~~~~^^^^^^^^^
[2025-02-18T16:07:43.327+0000] {subprocess.py:106} INFO - KeyError: 'dbt_bigquery://macros/adapters.sql'
[2025-02-18T16:07:43.328+0000] {subprocess.py:106} INFO - 
[2025-02-18T16:07:44.422+0000] {subprocess.py:110} INFO - Command exited with return code 2
[2025-02-18T16:07:44.437+0000] {taskinstance.py:3311} ERROR - Task failed with exception
Traceback (most recent call last):
  File "/home/airflow/.local/lib/python3.12/site-packages/airflow/models/taskinstance.py", line 767, in _execute_task
    result = _execute_callable(context=context, **execute_callable_kwargs)
             ^^^^^^^^^^^^^^^^^^^^^^^^^^^^^^^^^^^^^^^^^^^^^^^^^^^^^^^^^^^^^
  File "/home/airflow/.local/lib/python3.12/site-packages/airflow/models/taskinstance.py", line 733, in _execute_callable
    return ExecutionCallableRunner(
           ^^^^^^^^^^^^^^^^^^^^^^^^
  File "/home/airflow/.local/lib/python3.12/site-packages/airflow/utils/operator_helpers.py", line 252, in run
    return self.func(*args, **kwargs)
           ^^^^^^^^^^^^^^^^^^^^^^^^^^
  File "/home/airflow/.local/lib/python3.12/site-packages/airflow/models/baseoperator.py", line 422, in wrapper
    return func(self, *args, **kwargs)
           ^^^^^^^^^^^^^^^^^^^^^^^^^^^
  File "/home/airflow/.local/lib/python3.12/site-packages/airflow/operators/bash.py", line 276, in execute
    raise AirflowException(
airflow.exceptions.AirflowException: Bash command failed. The command returned a non-zero exit code 2.
[2025-02-18T16:07:44.443+0000] {taskinstance.py:1225} INFO - Marking task as FAILED. dag_id=dbt_run, task_id=run_dbt, run_id=scheduled__2025-02-18T15:40:00+00:00, execution_date=20250218T154000, start_date=20250218T160738, end_date=20250218T160744
[2025-02-18T16:07:44.460+0000] {taskinstance.py:340} INFO - ::group::Post task execution logs
[2025-02-18T16:07:44.461+0000] {standard_task_runner.py:124} ERROR - Failed to execute job 33 for task run_dbt (Bash command failed. The command returned a non-zero exit code 2.; 1095)
Traceback (most recent call last):
  File "/home/airflow/.local/lib/python3.12/site-packages/airflow/task/task_runner/standard_task_runner.py", line 117, in _start_by_fork
    ret = args.func(args, dag=self.dag)
          ^^^^^^^^^^^^^^^^^^^^^^^^^^^^^
  File "/home/airflow/.local/lib/python3.12/site-packages/airflow/cli/cli_config.py", line 49, in command
    return func(*args, **kwargs)
           ^^^^^^^^^^^^^^^^^^^^^
  File "/home/airflow/.local/lib/python3.12/site-packages/airflow/utils/cli.py", line 116, in wrapper
    return f(*args, **kwargs)
           ^^^^^^^^^^^^^^^^^^
  File "/home/airflow/.local/lib/python3.12/site-packages/airflow/cli/commands/task_command.py", line 483, in task_run
    task_return_code = _run_task_by_selected_method(args, _dag, ti)
                       ^^^^^^^^^^^^^^^^^^^^^^^^^^^^^^^^^^^^^^^^^^^^
  File "/home/airflow/.local/lib/python3.12/site-packages/airflow/cli/commands/task_command.py", line 256, in _run_task_by_selected_method
    return _run_raw_task(args, ti)
           ^^^^^^^^^^^^^^^^^^^^^^^
  File "/home/airflow/.local/lib/python3.12/site-packages/airflow/cli/commands/task_command.py", line 341, in _run_raw_task
    return ti._run_raw_task(
           ^^^^^^^^^^^^^^^^^
  File "/home/airflow/.local/lib/python3.12/site-packages/airflow/utils/session.py", line 97, in wrapper
    return func(*args, session=session, **kwargs)
           ^^^^^^^^^^^^^^^^^^^^^^^^^^^^^^^^^^^^^^
  File "/home/airflow/.local/lib/python3.12/site-packages/airflow/models/taskinstance.py", line 3005, in _run_raw_task
    return _run_raw_task(
           ^^^^^^^^^^^^^^
  File "/home/airflow/.local/lib/python3.12/site-packages/airflow/models/taskinstance.py", line 273, in _run_raw_task
    TaskInstance._execute_task_with_callbacks(
  File "/home/airflow/.local/lib/python3.12/site-packages/airflow/models/taskinstance.py", line 3159, in _execute_task_with_callbacks
    result = self._execute_task(context, task_orig)
             ^^^^^^^^^^^^^^^^^^^^^^^^^^^^^^^^^^^^^^
  File "/home/airflow/.local/lib/python3.12/site-packages/airflow/models/taskinstance.py", line 3183, in _execute_task
    return _execute_task(self, context, task_orig)
           ^^^^^^^^^^^^^^^^^^^^^^^^^^^^^^^^^^^^^^^
  File "/home/airflow/.local/lib/python3.12/site-packages/airflow/models/taskinstance.py", line 767, in _execute_task
    result = _execute_callable(context=context, **execute_callable_kwargs)
             ^^^^^^^^^^^^^^^^^^^^^^^^^^^^^^^^^^^^^^^^^^^^^^^^^^^^^^^^^^^^^
  File "/home/airflow/.local/lib/python3.12/site-packages/airflow/models/taskinstance.py", line 733, in _execute_callable
    return ExecutionCallableRunner(
           ^^^^^^^^^^^^^^^^^^^^^^^^
  File "/home/airflow/.local/lib/python3.12/site-packages/airflow/utils/operator_helpers.py", line 252, in run
    return self.func(*args, **kwargs)
           ^^^^^^^^^^^^^^^^^^^^^^^^^^
  File "/home/airflow/.local/lib/python3.12/site-packages/airflow/models/baseoperator.py", line 422, in wrapper
    return func(self, *args, **kwargs)
           ^^^^^^^^^^^^^^^^^^^^^^^^^^^
  File "/home/airflow/.local/lib/python3.12/site-packages/airflow/operators/bash.py", line 276, in execute
    raise AirflowException(
airflow.exceptions.AirflowException: Bash command failed. The command returned a non-zero exit code 2.
[2025-02-18T16:07:44.492+0000] {local_task_job_runner.py:266} INFO - Task exited with return code 1
[2025-02-18T16:07:44.510+0000] {taskinstance.py:3895} INFO - 0 downstream tasks scheduled from follow-on schedule check
[2025-02-18T16:07:44.514+0000] {local_task_job_runner.py:245} INFO - ::endgroup::
