[2025-02-18T21:05:10.264+0000] {local_task_job_runner.py:123} INFO - ::group::Pre task execution logs
[2025-02-18T21:05:10.293+0000] {taskinstance.py:2613} INFO - Dependencies all met for dep_context=non-requeueable deps ti=<TaskInstance: dbt_run.run_dbt scheduled__2025-02-18T20:40:00+00:00 [queued]>
[2025-02-18T21:05:10.311+0000] {taskinstance.py:2613} INFO - Dependencies all met for dep_context=requeueable deps ti=<TaskInstance: dbt_run.run_dbt scheduled__2025-02-18T20:40:00+00:00 [queued]>
[2025-02-18T21:05:10.312+0000] {taskinstance.py:2866} INFO - Starting attempt 2 of 2
[2025-02-18T21:05:10.342+0000] {taskinstance.py:2889} INFO - Executing <Task(BashOperator): run_dbt> on 2025-02-18 20:40:00+00:00
[2025-02-18T21:05:10.359+0000] {standard_task_runner.py:104} INFO - Running: ['***', 'tasks', 'run', 'dbt_run', 'run_dbt', 'scheduled__2025-02-18T20:40:00+00:00', '--job-id', '66', '--raw', '--subdir', 'DAGS_FOLDER/dbt_run_dag.py', '--cfg-path', '/tmp/tmpfhf0r5wc']
[2025-02-18T21:05:10.365+0000] {standard_task_runner.py:105} INFO - Job 66: Subtask run_dbt
[2025-02-18T21:05:10.374+0000] {logging_mixin.py:190} WARNING - /home/***/.local/lib/python3.12/site-packages/***/task/task_runner/standard_task_runner.py:70 DeprecationWarning: This process (pid=7525) is multi-threaded, use of fork() may lead to deadlocks in the child.
[2025-02-18T21:05:10.376+0000] {standard_task_runner.py:72} INFO - Started process 7526 to run task
[2025-02-18T21:05:10.470+0000] {task_command.py:467} INFO - Running <TaskInstance: dbt_run.run_dbt scheduled__2025-02-18T20:40:00+00:00 [running]> on host eeda3fda8711
[2025-02-18T21:05:10.657+0000] {taskinstance.py:3132} INFO - Exporting env vars: AIRFLOW_CTX_DAG_OWNER='***' AIRFLOW_CTX_DAG_ID='dbt_run' AIRFLOW_CTX_TASK_ID='run_dbt' AIRFLOW_CTX_EXECUTION_DATE='2025-02-18T20:40:00+00:00' AIRFLOW_CTX_TRY_NUMBER='2' AIRFLOW_CTX_DAG_RUN_ID='scheduled__2025-02-18T20:40:00+00:00'
[2025-02-18T21:05:10.658+0000] {taskinstance.py:731} INFO - ::endgroup::
[2025-02-18T21:05:10.684+0000] {subprocess.py:78} INFO - Tmp dir root location: /tmp
[2025-02-18T21:05:10.687+0000] {subprocess.py:88} INFO - Running command: ['/usr/bin/bash', '-c', 'cd /fitness-data-pipeline/fitness_dbt && dbt run']
[2025-02-18T21:05:10.700+0000] {subprocess.py:99} INFO - Output:
[2025-02-18T21:05:13.715+0000] {subprocess.py:106} INFO - [0m21:05:13  Running with dbt=1.9.2
[2025-02-18T21:05:15.821+0000] {subprocess.py:106} INFO - [0m21:05:15  Registered adapter: bigquery=1.9.1
[2025-02-18T21:05:16.736+0000] {subprocess.py:106} INFO - [0m21:05:16  Encountered an error:
[2025-02-18T21:05:16.736+0000] {subprocess.py:106} INFO - 'dbt_bigquery://macros/etc.sql'
[2025-02-18T21:05:16.738+0000] {subprocess.py:106} INFO - [0m21:05:16  Traceback (most recent call last):
[2025-02-18T21:05:16.738+0000] {subprocess.py:106} INFO -   File "/home/***/.local/lib/python3.12/site-packages/dbt/cli/requires.py", line 153, in wrapper
[2025-02-18T21:05:16.739+0000] {subprocess.py:106} INFO -     result, success = func(*args, **kwargs)
[2025-02-18T21:05:16.740+0000] {subprocess.py:106} INFO -                       ^^^^^^^^^^^^^^^^^^^^^
[2025-02-18T21:05:16.740+0000] {subprocess.py:106} INFO -   File "/home/***/.local/lib/python3.12/site-packages/dbt/cli/requires.py", line 103, in wrapper
[2025-02-18T21:05:16.741+0000] {subprocess.py:106} INFO -     return func(*args, **kwargs)
[2025-02-18T21:05:16.742+0000] {subprocess.py:106} INFO -            ^^^^^^^^^^^^^^^^^^^^^
[2025-02-18T21:05:16.743+0000] {subprocess.py:106} INFO -   File "/home/***/.local/lib/python3.12/site-packages/dbt/cli/requires.py", line 235, in wrapper
[2025-02-18T21:05:16.744+0000] {subprocess.py:106} INFO -     return func(*args, **kwargs)
[2025-02-18T21:05:16.744+0000] {subprocess.py:106} INFO -            ^^^^^^^^^^^^^^^^^^^^^
[2025-02-18T21:05:16.745+0000] {subprocess.py:106} INFO -   File "/home/***/.local/lib/python3.12/site-packages/dbt/cli/requires.py", line 264, in wrapper
[2025-02-18T21:05:16.745+0000] {subprocess.py:106} INFO -     return func(*args, **kwargs)
[2025-02-18T21:05:16.746+0000] {subprocess.py:106} INFO -            ^^^^^^^^^^^^^^^^^^^^^
[2025-02-18T21:05:16.746+0000] {subprocess.py:106} INFO -   File "/home/***/.local/lib/python3.12/site-packages/dbt/cli/requires.py", line 311, in wrapper
[2025-02-18T21:05:16.747+0000] {subprocess.py:106} INFO -     return func(*args, **kwargs)
[2025-02-18T21:05:16.748+0000] {subprocess.py:106} INFO -            ^^^^^^^^^^^^^^^^^^^^^
[2025-02-18T21:05:16.749+0000] {subprocess.py:106} INFO -   File "/home/***/.local/lib/python3.12/site-packages/dbt/cli/requires.py", line 327, in wrapper
[2025-02-18T21:05:16.750+0000] {subprocess.py:106} INFO -     setup_manifest(ctx, write=write, write_perf_info=write_perf_info)
[2025-02-18T21:05:16.751+0000] {subprocess.py:106} INFO -   File "/home/***/.local/lib/python3.12/site-packages/dbt/cli/requires.py", line 351, in setup_manifest
[2025-02-18T21:05:16.752+0000] {subprocess.py:106} INFO -     ctx.obj["manifest"] = parse_manifest(
[2025-02-18T21:05:16.752+0000] {subprocess.py:106} INFO -                           ^^^^^^^^^^^^^^^
[2025-02-18T21:05:16.753+0000] {subprocess.py:106} INFO -   File "/home/***/.local/lib/python3.12/site-packages/dbt/parser/manifest.py", line 2069, in parse_manifest
[2025-02-18T21:05:16.754+0000] {subprocess.py:106} INFO -     manifest = ManifestLoader.get_full_manifest(
[2025-02-18T21:05:16.754+0000] {subprocess.py:106} INFO -                ^^^^^^^^^^^^^^^^^^^^^^^^^^^^^^^^^
[2025-02-18T21:05:16.755+0000] {subprocess.py:106} INFO -   File "/home/***/.local/lib/python3.12/site-packages/dbt/parser/manifest.py", line 312, in get_full_manifest
[2025-02-18T21:05:16.756+0000] {subprocess.py:106} INFO -     manifest = loader.load()
[2025-02-18T21:05:16.757+0000] {subprocess.py:106} INFO -                ^^^^^^^^^^^^^
[2025-02-18T21:05:16.758+0000] {subprocess.py:106} INFO -   File "/home/***/.local/lib/python3.12/site-packages/dbt/parser/manifest.py", line 381, in load
[2025-02-18T21:05:16.759+0000] {subprocess.py:106} INFO -     self.load_and_parse_macros(project_parser_files)
[2025-02-18T21:05:16.759+0000] {subprocess.py:106} INFO -   File "/home/***/.local/lib/python3.12/site-packages/dbt/parser/manifest.py", line 683, in load_and_parse_macros
[2025-02-18T21:05:16.760+0000] {subprocess.py:106} INFO -     block = FileBlock(self.manifest.files[file_id])
[2025-02-18T21:05:16.761+0000] {subprocess.py:106} INFO -                       ~~~~~~~~~~~~~~~~~~~^^^^^^^^^
[2025-02-18T21:05:16.762+0000] {subprocess.py:106} INFO - KeyError: 'dbt_bigquery://macros/etc.sql'
[2025-02-18T21:05:16.763+0000] {subprocess.py:106} INFO - 
[2025-02-18T21:05:17.937+0000] {subprocess.py:110} INFO - Command exited with return code 2
[2025-02-18T21:05:17.948+0000] {taskinstance.py:3311} ERROR - Task failed with exception
Traceback (most recent call last):
  File "/home/airflow/.local/lib/python3.12/site-packages/airflow/models/taskinstance.py", line 767, in _execute_task
    result = _execute_callable(context=context, **execute_callable_kwargs)
             ^^^^^^^^^^^^^^^^^^^^^^^^^^^^^^^^^^^^^^^^^^^^^^^^^^^^^^^^^^^^^
  File "/home/airflow/.local/lib/python3.12/site-packages/airflow/models/taskinstance.py", line 733, in _execute_callable
    return ExecutionCallableRunner(
           ^^^^^^^^^^^^^^^^^^^^^^^^
  File "/home/airflow/.local/lib/python3.12/site-packages/airflow/utils/operator_helpers.py", line 252, in run
    return self.func(*args, **kwargs)
           ^^^^^^^^^^^^^^^^^^^^^^^^^^
  File "/home/airflow/.local/lib/python3.12/site-packages/airflow/models/baseoperator.py", line 422, in wrapper
    return func(self, *args, **kwargs)
           ^^^^^^^^^^^^^^^^^^^^^^^^^^^
  File "/home/airflow/.local/lib/python3.12/site-packages/airflow/operators/bash.py", line 276, in execute
    raise AirflowException(
airflow.exceptions.AirflowException: Bash command failed. The command returned a non-zero exit code 2.
[2025-02-18T21:05:17.953+0000] {taskinstance.py:1225} INFO - Marking task as FAILED. dag_id=dbt_run, task_id=run_dbt, run_id=scheduled__2025-02-18T20:40:00+00:00, execution_date=20250218T204000, start_date=20250218T210510, end_date=20250218T210517
[2025-02-18T21:05:17.969+0000] {taskinstance.py:340} INFO - ::group::Post task execution logs
[2025-02-18T21:05:17.970+0000] {standard_task_runner.py:124} ERROR - Failed to execute job 66 for task run_dbt (Bash command failed. The command returned a non-zero exit code 2.; 7526)
Traceback (most recent call last):
  File "/home/airflow/.local/lib/python3.12/site-packages/airflow/task/task_runner/standard_task_runner.py", line 117, in _start_by_fork
    ret = args.func(args, dag=self.dag)
          ^^^^^^^^^^^^^^^^^^^^^^^^^^^^^
  File "/home/airflow/.local/lib/python3.12/site-packages/airflow/cli/cli_config.py", line 49, in command
    return func(*args, **kwargs)
           ^^^^^^^^^^^^^^^^^^^^^
  File "/home/airflow/.local/lib/python3.12/site-packages/airflow/utils/cli.py", line 116, in wrapper
    return f(*args, **kwargs)
           ^^^^^^^^^^^^^^^^^^
  File "/home/airflow/.local/lib/python3.12/site-packages/airflow/cli/commands/task_command.py", line 483, in task_run
    task_return_code = _run_task_by_selected_method(args, _dag, ti)
                       ^^^^^^^^^^^^^^^^^^^^^^^^^^^^^^^^^^^^^^^^^^^^
  File "/home/airflow/.local/lib/python3.12/site-packages/airflow/cli/commands/task_command.py", line 256, in _run_task_by_selected_method
    return _run_raw_task(args, ti)
           ^^^^^^^^^^^^^^^^^^^^^^^
  File "/home/airflow/.local/lib/python3.12/site-packages/airflow/cli/commands/task_command.py", line 341, in _run_raw_task
    return ti._run_raw_task(
           ^^^^^^^^^^^^^^^^^
  File "/home/airflow/.local/lib/python3.12/site-packages/airflow/utils/session.py", line 97, in wrapper
    return func(*args, session=session, **kwargs)
           ^^^^^^^^^^^^^^^^^^^^^^^^^^^^^^^^^^^^^^
  File "/home/airflow/.local/lib/python3.12/site-packages/airflow/models/taskinstance.py", line 3005, in _run_raw_task
    return _run_raw_task(
           ^^^^^^^^^^^^^^
  File "/home/airflow/.local/lib/python3.12/site-packages/airflow/models/taskinstance.py", line 273, in _run_raw_task
    TaskInstance._execute_task_with_callbacks(
  File "/home/airflow/.local/lib/python3.12/site-packages/airflow/models/taskinstance.py", line 3159, in _execute_task_with_callbacks
    result = self._execute_task(context, task_orig)
             ^^^^^^^^^^^^^^^^^^^^^^^^^^^^^^^^^^^^^^
  File "/home/airflow/.local/lib/python3.12/site-packages/airflow/models/taskinstance.py", line 3183, in _execute_task
    return _execute_task(self, context, task_orig)
           ^^^^^^^^^^^^^^^^^^^^^^^^^^^^^^^^^^^^^^^
  File "/home/airflow/.local/lib/python3.12/site-packages/airflow/models/taskinstance.py", line 767, in _execute_task
    result = _execute_callable(context=context, **execute_callable_kwargs)
             ^^^^^^^^^^^^^^^^^^^^^^^^^^^^^^^^^^^^^^^^^^^^^^^^^^^^^^^^^^^^^
  File "/home/airflow/.local/lib/python3.12/site-packages/airflow/models/taskinstance.py", line 733, in _execute_callable
    return ExecutionCallableRunner(
           ^^^^^^^^^^^^^^^^^^^^^^^^
  File "/home/airflow/.local/lib/python3.12/site-packages/airflow/utils/operator_helpers.py", line 252, in run
    return self.func(*args, **kwargs)
           ^^^^^^^^^^^^^^^^^^^^^^^^^^
  File "/home/airflow/.local/lib/python3.12/site-packages/airflow/models/baseoperator.py", line 422, in wrapper
    return func(self, *args, **kwargs)
           ^^^^^^^^^^^^^^^^^^^^^^^^^^^
  File "/home/airflow/.local/lib/python3.12/site-packages/airflow/operators/bash.py", line 276, in execute
    raise AirflowException(
airflow.exceptions.AirflowException: Bash command failed. The command returned a non-zero exit code 2.
[2025-02-18T21:05:18.013+0000] {local_task_job_runner.py:266} INFO - Task exited with return code 1
[2025-02-18T21:05:18.033+0000] {taskinstance.py:3895} INFO - 0 downstream tasks scheduled from follow-on schedule check
[2025-02-18T21:05:18.038+0000] {local_task_job_runner.py:245} INFO - ::endgroup::
