[2025-02-18T19:25:10.413+0000] {local_task_job_runner.py:123} INFO - ::group::Pre task execution logs
[2025-02-18T19:25:10.441+0000] {taskinstance.py:2613} INFO - Dependencies all met for dep_context=non-requeueable deps ti=<TaskInstance: dbt_run.run_dbt scheduled__2025-02-18T19:00:00+00:00 [queued]>
[2025-02-18T19:25:10.457+0000] {taskinstance.py:2613} INFO - Dependencies all met for dep_context=requeueable deps ti=<TaskInstance: dbt_run.run_dbt scheduled__2025-02-18T19:00:00+00:00 [queued]>
[2025-02-18T19:25:10.459+0000] {taskinstance.py:2866} INFO - Starting attempt 2 of 2
[2025-02-18T19:25:10.485+0000] {taskinstance.py:2889} INFO - Executing <Task(BashOperator): run_dbt> on 2025-02-18 19:00:00+00:00
[2025-02-18T19:25:10.497+0000] {standard_task_runner.py:104} INFO - Running: ['***', 'tasks', 'run', 'dbt_run', 'run_dbt', 'scheduled__2025-02-18T19:00:00+00:00', '--job-id', '56', '--raw', '--subdir', 'DAGS_FOLDER/dbt_run_dag.py', '--cfg-path', '/tmp/tmpopcf90d2']
[2025-02-18T19:25:10.501+0000] {standard_task_runner.py:105} INFO - Job 56: Subtask run_dbt
[2025-02-18T19:25:10.501+0000] {logging_mixin.py:190} WARNING - /home/***/.local/lib/python3.12/site-packages/***/task/task_runner/standard_task_runner.py:70 DeprecationWarning: This process (pid=5475) is multi-threaded, use of fork() may lead to deadlocks in the child.
[2025-02-18T19:25:10.503+0000] {standard_task_runner.py:72} INFO - Started process 5476 to run task
[2025-02-18T19:25:10.583+0000] {task_command.py:467} INFO - Running <TaskInstance: dbt_run.run_dbt scheduled__2025-02-18T19:00:00+00:00 [running]> on host eeda3fda8711
[2025-02-18T19:25:10.723+0000] {taskinstance.py:3132} INFO - Exporting env vars: AIRFLOW_CTX_DAG_OWNER='***' AIRFLOW_CTX_DAG_ID='dbt_run' AIRFLOW_CTX_TASK_ID='run_dbt' AIRFLOW_CTX_EXECUTION_DATE='2025-02-18T19:00:00+00:00' AIRFLOW_CTX_TRY_NUMBER='2' AIRFLOW_CTX_DAG_RUN_ID='scheduled__2025-02-18T19:00:00+00:00'
[2025-02-18T19:25:10.725+0000] {taskinstance.py:731} INFO - ::endgroup::
[2025-02-18T19:25:10.749+0000] {subprocess.py:78} INFO - Tmp dir root location: /tmp
[2025-02-18T19:25:10.754+0000] {subprocess.py:88} INFO - Running command: ['/usr/bin/bash', '-c', 'cd /fitness-data-pipeline/fitness_dbt && dbt run']
[2025-02-18T19:25:10.771+0000] {subprocess.py:99} INFO - Output:
[2025-02-18T19:25:13.744+0000] {subprocess.py:106} INFO - [0m19:25:13  Running with dbt=1.9.2
[2025-02-18T19:25:15.261+0000] {subprocess.py:106} INFO - [0m19:25:15  Registered adapter: bigquery=1.9.1
[2025-02-18T19:25:16.197+0000] {subprocess.py:106} INFO - [0m19:25:16  Encountered an error:
[2025-02-18T19:25:16.198+0000] {subprocess.py:106} INFO - 'dbt_bigquery://macros/adapters.sql'
[2025-02-18T19:25:16.200+0000] {subprocess.py:106} INFO - [0m19:25:16  Traceback (most recent call last):
[2025-02-18T19:25:16.201+0000] {subprocess.py:106} INFO -   File "/home/***/.local/lib/python3.12/site-packages/dbt/cli/requires.py", line 153, in wrapper
[2025-02-18T19:25:16.202+0000] {subprocess.py:106} INFO -     result, success = func(*args, **kwargs)
[2025-02-18T19:25:16.203+0000] {subprocess.py:106} INFO -                       ^^^^^^^^^^^^^^^^^^^^^
[2025-02-18T19:25:16.204+0000] {subprocess.py:106} INFO -   File "/home/***/.local/lib/python3.12/site-packages/dbt/cli/requires.py", line 103, in wrapper
[2025-02-18T19:25:16.205+0000] {subprocess.py:106} INFO -     return func(*args, **kwargs)
[2025-02-18T19:25:16.206+0000] {subprocess.py:106} INFO -            ^^^^^^^^^^^^^^^^^^^^^
[2025-02-18T19:25:16.207+0000] {subprocess.py:106} INFO -   File "/home/***/.local/lib/python3.12/site-packages/dbt/cli/requires.py", line 235, in wrapper
[2025-02-18T19:25:16.208+0000] {subprocess.py:106} INFO -     return func(*args, **kwargs)
[2025-02-18T19:25:16.209+0000] {subprocess.py:106} INFO -            ^^^^^^^^^^^^^^^^^^^^^
[2025-02-18T19:25:16.210+0000] {subprocess.py:106} INFO -   File "/home/***/.local/lib/python3.12/site-packages/dbt/cli/requires.py", line 264, in wrapper
[2025-02-18T19:25:16.211+0000] {subprocess.py:106} INFO -     return func(*args, **kwargs)
[2025-02-18T19:25:16.213+0000] {subprocess.py:106} INFO -            ^^^^^^^^^^^^^^^^^^^^^
[2025-02-18T19:25:16.214+0000] {subprocess.py:106} INFO -   File "/home/***/.local/lib/python3.12/site-packages/dbt/cli/requires.py", line 311, in wrapper
[2025-02-18T19:25:16.215+0000] {subprocess.py:106} INFO -     return func(*args, **kwargs)
[2025-02-18T19:25:16.215+0000] {subprocess.py:106} INFO -            ^^^^^^^^^^^^^^^^^^^^^
[2025-02-18T19:25:16.216+0000] {subprocess.py:106} INFO -   File "/home/***/.local/lib/python3.12/site-packages/dbt/cli/requires.py", line 327, in wrapper
[2025-02-18T19:25:16.216+0000] {subprocess.py:106} INFO -     setup_manifest(ctx, write=write, write_perf_info=write_perf_info)
[2025-02-18T19:25:16.217+0000] {subprocess.py:106} INFO -   File "/home/***/.local/lib/python3.12/site-packages/dbt/cli/requires.py", line 351, in setup_manifest
[2025-02-18T19:25:16.218+0000] {subprocess.py:106} INFO -     ctx.obj["manifest"] = parse_manifest(
[2025-02-18T19:25:16.218+0000] {subprocess.py:106} INFO -                           ^^^^^^^^^^^^^^^
[2025-02-18T19:25:16.219+0000] {subprocess.py:106} INFO -   File "/home/***/.local/lib/python3.12/site-packages/dbt/parser/manifest.py", line 2069, in parse_manifest
[2025-02-18T19:25:16.220+0000] {subprocess.py:106} INFO -     manifest = ManifestLoader.get_full_manifest(
[2025-02-18T19:25:16.220+0000] {subprocess.py:106} INFO -                ^^^^^^^^^^^^^^^^^^^^^^^^^^^^^^^^^
[2025-02-18T19:25:16.221+0000] {subprocess.py:106} INFO -   File "/home/***/.local/lib/python3.12/site-packages/dbt/parser/manifest.py", line 312, in get_full_manifest
[2025-02-18T19:25:16.222+0000] {subprocess.py:106} INFO -     manifest = loader.load()
[2025-02-18T19:25:16.222+0000] {subprocess.py:106} INFO -                ^^^^^^^^^^^^^
[2025-02-18T19:25:16.223+0000] {subprocess.py:106} INFO -   File "/home/***/.local/lib/python3.12/site-packages/dbt/parser/manifest.py", line 381, in load
[2025-02-18T19:25:16.224+0000] {subprocess.py:106} INFO -     self.load_and_parse_macros(project_parser_files)
[2025-02-18T19:25:16.224+0000] {subprocess.py:106} INFO -   File "/home/***/.local/lib/python3.12/site-packages/dbt/parser/manifest.py", line 683, in load_and_parse_macros
[2025-02-18T19:25:16.225+0000] {subprocess.py:106} INFO -     block = FileBlock(self.manifest.files[file_id])
[2025-02-18T19:25:16.226+0000] {subprocess.py:106} INFO -                       ~~~~~~~~~~~~~~~~~~~^^^^^^^^^
[2025-02-18T19:25:16.226+0000] {subprocess.py:106} INFO - KeyError: 'dbt_bigquery://macros/adapters.sql'
[2025-02-18T19:25:16.227+0000] {subprocess.py:106} INFO - 
[2025-02-18T19:25:17.736+0000] {subprocess.py:110} INFO - Command exited with return code 2
[2025-02-18T19:25:17.754+0000] {taskinstance.py:3311} ERROR - Task failed with exception
Traceback (most recent call last):
  File "/home/airflow/.local/lib/python3.12/site-packages/airflow/models/taskinstance.py", line 767, in _execute_task
    result = _execute_callable(context=context, **execute_callable_kwargs)
             ^^^^^^^^^^^^^^^^^^^^^^^^^^^^^^^^^^^^^^^^^^^^^^^^^^^^^^^^^^^^^
  File "/home/airflow/.local/lib/python3.12/site-packages/airflow/models/taskinstance.py", line 733, in _execute_callable
    return ExecutionCallableRunner(
           ^^^^^^^^^^^^^^^^^^^^^^^^
  File "/home/airflow/.local/lib/python3.12/site-packages/airflow/utils/operator_helpers.py", line 252, in run
    return self.func(*args, **kwargs)
           ^^^^^^^^^^^^^^^^^^^^^^^^^^
  File "/home/airflow/.local/lib/python3.12/site-packages/airflow/models/baseoperator.py", line 422, in wrapper
    return func(self, *args, **kwargs)
           ^^^^^^^^^^^^^^^^^^^^^^^^^^^
  File "/home/airflow/.local/lib/python3.12/site-packages/airflow/operators/bash.py", line 276, in execute
    raise AirflowException(
airflow.exceptions.AirflowException: Bash command failed. The command returned a non-zero exit code 2.
[2025-02-18T19:25:17.762+0000] {taskinstance.py:1225} INFO - Marking task as FAILED. dag_id=dbt_run, task_id=run_dbt, run_id=scheduled__2025-02-18T19:00:00+00:00, execution_date=20250218T190000, start_date=20250218T192510, end_date=20250218T192517
[2025-02-18T19:25:17.796+0000] {taskinstance.py:340} INFO - ::group::Post task execution logs
[2025-02-18T19:25:17.798+0000] {standard_task_runner.py:124} ERROR - Failed to execute job 56 for task run_dbt (Bash command failed. The command returned a non-zero exit code 2.; 5476)
Traceback (most recent call last):
  File "/home/airflow/.local/lib/python3.12/site-packages/airflow/task/task_runner/standard_task_runner.py", line 117, in _start_by_fork
    ret = args.func(args, dag=self.dag)
          ^^^^^^^^^^^^^^^^^^^^^^^^^^^^^
  File "/home/airflow/.local/lib/python3.12/site-packages/airflow/cli/cli_config.py", line 49, in command
    return func(*args, **kwargs)
           ^^^^^^^^^^^^^^^^^^^^^
  File "/home/airflow/.local/lib/python3.12/site-packages/airflow/utils/cli.py", line 116, in wrapper
    return f(*args, **kwargs)
           ^^^^^^^^^^^^^^^^^^
  File "/home/airflow/.local/lib/python3.12/site-packages/airflow/cli/commands/task_command.py", line 483, in task_run
    task_return_code = _run_task_by_selected_method(args, _dag, ti)
                       ^^^^^^^^^^^^^^^^^^^^^^^^^^^^^^^^^^^^^^^^^^^^
  File "/home/airflow/.local/lib/python3.12/site-packages/airflow/cli/commands/task_command.py", line 256, in _run_task_by_selected_method
    return _run_raw_task(args, ti)
           ^^^^^^^^^^^^^^^^^^^^^^^
  File "/home/airflow/.local/lib/python3.12/site-packages/airflow/cli/commands/task_command.py", line 341, in _run_raw_task
    return ti._run_raw_task(
           ^^^^^^^^^^^^^^^^^
  File "/home/airflow/.local/lib/python3.12/site-packages/airflow/utils/session.py", line 97, in wrapper
    return func(*args, session=session, **kwargs)
           ^^^^^^^^^^^^^^^^^^^^^^^^^^^^^^^^^^^^^^
  File "/home/airflow/.local/lib/python3.12/site-packages/airflow/models/taskinstance.py", line 3005, in _run_raw_task
    return _run_raw_task(
           ^^^^^^^^^^^^^^
  File "/home/airflow/.local/lib/python3.12/site-packages/airflow/models/taskinstance.py", line 273, in _run_raw_task
    TaskInstance._execute_task_with_callbacks(
  File "/home/airflow/.local/lib/python3.12/site-packages/airflow/models/taskinstance.py", line 3159, in _execute_task_with_callbacks
    result = self._execute_task(context, task_orig)
             ^^^^^^^^^^^^^^^^^^^^^^^^^^^^^^^^^^^^^^
  File "/home/airflow/.local/lib/python3.12/site-packages/airflow/models/taskinstance.py", line 3183, in _execute_task
    return _execute_task(self, context, task_orig)
           ^^^^^^^^^^^^^^^^^^^^^^^^^^^^^^^^^^^^^^^
  File "/home/airflow/.local/lib/python3.12/site-packages/airflow/models/taskinstance.py", line 767, in _execute_task
    result = _execute_callable(context=context, **execute_callable_kwargs)
             ^^^^^^^^^^^^^^^^^^^^^^^^^^^^^^^^^^^^^^^^^^^^^^^^^^^^^^^^^^^^^
  File "/home/airflow/.local/lib/python3.12/site-packages/airflow/models/taskinstance.py", line 733, in _execute_callable
    return ExecutionCallableRunner(
           ^^^^^^^^^^^^^^^^^^^^^^^^
  File "/home/airflow/.local/lib/python3.12/site-packages/airflow/utils/operator_helpers.py", line 252, in run
    return self.func(*args, **kwargs)
           ^^^^^^^^^^^^^^^^^^^^^^^^^^
  File "/home/airflow/.local/lib/python3.12/site-packages/airflow/models/baseoperator.py", line 422, in wrapper
    return func(self, *args, **kwargs)
           ^^^^^^^^^^^^^^^^^^^^^^^^^^^
  File "/home/airflow/.local/lib/python3.12/site-packages/airflow/operators/bash.py", line 276, in execute
    raise AirflowException(
airflow.exceptions.AirflowException: Bash command failed. The command returned a non-zero exit code 2.
[2025-02-18T19:25:17.825+0000] {local_task_job_runner.py:266} INFO - Task exited with return code 1
[2025-02-18T19:25:17.851+0000] {taskinstance.py:3895} INFO - 0 downstream tasks scheduled from follow-on schedule check
[2025-02-18T19:25:17.857+0000] {local_task_job_runner.py:245} INFO - ::endgroup::
